Workbook

Sheet 1. T-Shirt Combed Premium - Sab
B2: T-Shirt Combed Premium - Sablon | C2: Total Harga/Pcs
B3: Bahan | C3: =SUM('249 T-shirt Custom'!J10:J11) -> 0
B4: Aksesoris | C4: =SUM('249 T-shirt Custom'!J14:J20) -> 1578.7
B5: Pekerja | C5: =SUM('249 T-shirt Custom'!J24:J27) -> 7250
B6: Total Biaya Per Pcs | C6: =SUM(C3:D5) -> 8828.7

Sheet 2. T-Shirt Combed Reguler - Sab
B2: T-Shirt Combed Reguler - Sablon | C2: Total Harga/Pcs
B3: Bahan | C3: =SUM(J10:J11) -> 26225.391
B4: Aksesoris | C4: =SUM(J14:J20) -> 4078.7
B5: Pekerja | C5: =SUM(J23:J26) -> 7250
B6: Total Biaya Per Pcs | C6: =SUM(C3:D5) -> 37554.091
A8: BAHAN UTAMA
A9: NO | B9: BAHAN | C9: WARNA | D9: PEMAKAIAN | E9: UNIT | F9: KETERANGAN Pemakaian | G9: VENDOR | H9: HARGA ECER | I9: HARGA ROLL | J9: HARGA / PCS
A10: 1 | B10: Cotton Combed Reguler | C10: Hitam | D10: =1/4.6 -> 0.2173913 | E10: Kg | F10: 1 kg untuk 4,6 Pcs | G10: Fokus | H10: 116000 | J10: =D10*H10 -> 25217.391
A11: 2 | B11: Rib Cotton Combed Reguler | C11: Hitam | D11: =1/125 -> 0.008 | E11: Kg | F11: 1 Kg untuk 125 Pcs | G11: Fokus | H11: 126000 | J11: =D11*H11 -> 1008
A12: AKSESORIS
A13: NO | B13: BAHAN | C13: WARNA | D13: PEMAKAIAN | E13: UNIT | F13: KET. PEMAKAIAN | G13: VENDOR | H13: HARGA ECER | I13: HARGA ROLL | J13: HARGA / PCS
A14: 1 | B14: Benang Jahit | C14: Hitam | D14: =4/100 -> 0.04 | E14: Lusin | F14: 1 lusin jadi 100pc | G14: Toko 1001 | H14: 25000 | J14: =D14*H14 -> 1000
A15: 2 | B15: Benang Obras | C15: Hitam | D15: 0 | E15: Cones | F15: 4 cones jadi 120pc | G15: Toko 1001 | H15: 13000 | J15: =D15*H15 -> 0
A16: 3 | B16: Label Size Bordir | C16: Hitam | D16: =1/100 -> 0.01 | E16: Golong | F16: 1 Golong Jadi 100 pc | G16: Toko 1001 | H16: 10000 | J16: =D16*H16 -> 100
A17: 4 | B17: Plastik Opp 30 Micron | C17: Bening | D17: 1 | E17: Pcs | F17: 1 Plastik 1 Pcs | G17: Mapan Plastik | H17: 370 | J17: =D17*H17 -> 370
A18: 5 | B18: Plastik Pp 50x60cm | C18: Bening | D18: =1/10 -> 0.1 | E18: Pcs | F18: 1 Plastik 10 Pcs | G18: Istana Plastik | H18: 587 | J18: =D18*H18 -> 58.7
A19: 6 | B19: Karung | C19: Putih | D19: =1/100 -> 0.01 | E19: Pcs | F19: 1 karung 100 pcs | G19: Cibadak | H19: 5000 | J19: =D19*H19 -> 50
A20: 7 | B20: Cat Sablon Plastisol | C20: Mix Warna | D20: 1 | E20: Pcs | F20: - | G20: Metro SPS | H20: 2500 | J20: =D20*H20 -> 2500
A21: Manufaktur
A22: NO | B22: WORK | D22: PEMAKAIAN | E22: UNIT | F22: KET. PEMAKAIAN | G22: VENDOR | H22: ESTIMASI MIN | J22: HARGA / PCS
A23: 1 | B23: Cutting T-Shirt | D23: 1 | E23: Pcs | G23: VML | H23: 750 | J23: =D23*H23 -> 750
A24: 2 | B24: Sablon T-Shirt | D24: 1 | E24: Pcs | G24: VML | H24: 2000 | J24: =D24*H24 -> 2000
A25: 3 | B25: Jahit T-Shirt | D25: 1 | E25: Pcs | G25: VML | H25: 2500 | J25: =D25*H25 -> 2500
A26: 4 | B26: QC T-Shirt | D26: 1 | E26: Pcs | G26: VML | H26: 2000 | J26: =D26*H26 -> 2000

Sheet 3. T-Shirt Combed Premium - DTF
B2: T-Shirt Combed Premium - DTF | C2: Total Harga/Pcs
B3: Bahan | C3: =SUM(J10:J11) -> 30451.826
B4: Aksesoris | C4: =SUM(J14:J20) -> 5328.7
B5: Pekerja | C5: =SUM(J23:J26) -> 6750
B6: Total Biaya Per Pcs | C6: =SUM(C3:D5) -> 42530.526
A8: BAHAN UTAMA
A9: NO | B9: BAHAN | C9: WARNA | D9: PEMAKAIAN | E9: UNIT | F9: KETERANGAN Pemakaian | G9: VENDOR | H9: HARGA ECER | I9: HARGA ROLL | J9: HARGA / PCS
A10: 1 | B10: Cotton Combed Premium | C10: Hitam | D10: =1/4.6 -> 0.2173913 | E10: Kg | F10: 1 kg untuk 4,6 Pcs | G10: CV. Terang Mulia Bandung | H10: 135000 | J10: =D10*H10 -> 29347.826
A11: 2 | B11: Rib Cotton Combed Premium | C11: Hitam | D11: =1/125 -> 0.008 | E11: Kg | F11: 1 Kg untuk 125 Pcs | G11: CV. Terang Mulia Bandung | H11: 138000 | J11: =D11*H11 -> 1104
A12: AKSESORIS
A13: NO | B13: BAHAN | C13: WARNA | D13: PEMAKAIAN | E13: UNIT | F13: KET. PEMAKAIAN | G13: VENDOR | H13: HARGA ECER | I13: HARGA ROLL | J13: HARGA / PCS
A14: 1 | B14: Benang Jahit | C14: Hitam | D14: =4/100 -> 0.04 | E14: Lusin | F14: 1 lusin jadi 100pc | G14: Toko 1001 | H14: 25000 | J14: =D14*H14 -> 1000
A15: 2 | B15: Benang Obras | C15: Hitam | D15: 0 | E15: Cones | F15: 4 cones jadi 120pc | G15: Toko 1001 | H15: 13000 | J15: =D15*H15 -> 0
A16: 3 | B16: Label Size Bordir | C16: Hitam | D16: =1/100 -> 0.01 | E16: Golong | F16: 1 Golong Jadi 100 pc | G16: Toko 1001 | H16: 10000 | J16: =D16*H16 -> 100
A17: 4 | B17: Plastik Opp 30 Micron | C17: Bening | D17: 1 | E17: Pcs | F17: 1 Plastik 1 Pcs | G17: Mapan Plastik | H17: 370 | J17: =D17*H17 -> 370
A18: 5 | B18: Plastik Pp 50x60cm | C18: Bening | D18: =1/10 -> 0.1 | E18: Pcs | F18: 1 Plastik 10 Pcs | G18: Istana Plastik | H18: 587 | J18: =D18*H18 -> 58.7
A19: 6 | B19: Karung | C19: Putih | D19: =1/100 -> 0.01 | E19: Pcs | F19: 1 karung 100 pcs | G19: Cibadak | H19: 5000 | J19: =D19*H19 -> 50
A20: 7 | B20: DTF | C20: Mix Warna | D20: 1 | E20: Pcs | F20: - | G20: Max Print | H20: 3750 | J20: =D20*H20 -> 3750
A21: Manufaktur
A22: NO | B22: WORK | D22: PEMAKAIAN | E22: UNIT | F22: KET. PEMAKAIAN | G22: VENDOR | H22: ESTIMASI MIN | J22: HARGA / PCS
A23: 1 | B23: Cutting T-Shirt | D23: 1 | E23: Pcs | G23: VML | H23: 750 | J23: =D23*H23 -> 750
A24: 2 | B24: Sablon T-Shirt | D24: 1 | E24: Pcs | G24: VML | H24: 1500 | J24: =D24*H24 -> 1500
A25: 3 | B25: Jahit T-Shirt | D25: 1 | E25: Pcs | G25: VML | H25: 2500 | J25: =D25*H25 -> 2500
A26: 4 | B26: QC T-Shirt | D26: 1 | E26: Pcs | G26: VML | H26: 2000 | J26: =D26*H26 -> 2000

Sheet 4. T-Shirt Combed Reguler - DTF
B2: T-Shirt Combed Reguler - DTF | C2: Total Harga/Pcs
B3: Bahan | C3: =SUM(J10:J11) -> 26225.391
B4: Aksesoris | C4: =SUM(J14:J20) -> 5328.7
B5: Pekerja | C5: =SUM(J23:J26) -> 6750
B6: Total Biaya Per Pcs | C6: =SUM(C3:D5) -> 38304.091
A8: BAHAN UTAMA
A9: NO | B9: BAHAN | C9: WARNA | D9: PEMAKAIAN | E9: UNIT | F9: KETERANGAN Pemakaian | G9: VENDOR | H9: HARGA ECER | I9: HARGA ROLL | J9: HARGA / PCS
A10: 1 | B10: Cotton Combed reguler | C10: Hitam | D10: =1/4.6 -> 0.2173913 | E10: Kg | F10: 1 kg untuk 4,6 Pcs | G10: Fokus | H10: 116000 | J10: =D10*H10 -> 25217.391
A11: 2 | B11: Rib Cotton Combed Reguler | C11: Hitam | D11: =1/125 -> 0.008 | E11: Kg | F11: 1 Kg untuk 125 Pcs | G11: Fokus | H11: 126000 | J11: =D11*H11 -> 1008
A12: AKSESORIS
A13: NO | B13: BAHAN | C13: WARNA | D13: PEMAKAIAN | E13: UNIT | F13: KET. PEMAKAIAN | G13: VENDOR | H13: HARGA ECER | I13: HARGA ROLL | J13: HARGA / PCS
A14: 1 | B14: Benang Jahit | C14: Hitam | D14: =4/100 -> 0.04 | E14: Lusin | F14: 1 lusin jadi 100pc | G14: Toko 1001 | H14: 25000 | J14: =D14*H14 -> 1000
A15: 2 | B15: Benang Obras | C15: Hitam | D15: 0 | E15: Cones | F15: 4 cones jadi 120pc | G15: Toko 1001 | H15: 13000 | J15: =D15*H15 -> 0
A16: 3 | B16: Label Size Bordir | C16: Hitam | D16: =1/100 -> 0.01 | E16: Golong | F16: 1 Golong Jadi 100 pc | G16: Toko 1001 | H16: 10000 | J16: =D16*H16 -> 100
A17: 4 | B17: Plastik Opp 30 Micron | C17: Bening | D17: 1 | E17: Pcs | F17: 1 Plastik 1 Pcs | G17: Mapan Plastik | H17: 370 | J17: =D17*H17 -> 370
A18: 5 | B18: Plastik Pp 50x60cm | C18: Bening | D18: =1/10 -> 0.1 | E18: Pcs | F18: 1 Plastik 10 Pcs | G18: Istana Plastik | H18: 587 | J18: =D18*H18 -> 58.7
A19: 6 | B19: Karung | C19: Putih | D19: =1/100 -> 0.01 | E19: Pcs | F19: 1 karung 100 pcs | G19: Cibadak | H19: 5000 | J19: =D19*H19 -> 50
A20: 7 | B20: DTF | C20: Mix Warna | D20: 1 | E20: Pcs | F20: - | G20: Max Print | H20: 3750 | J20: =D20*H20 -> 3750
A21: Manufaktur
A22: NO | B22: WORK | D22: PEMAKAIAN | E22: UNIT | F22: KET. PEMAKAIAN | G22: VENDOR | H22: ESTIMASI MIN | J22: HARGA / PCS
A23: 1 | B23: Cutting T-Shirt | D23: 1 | E23: Pcs | G23: VML | H23: 750 | J23: =D23*H23 -> 750
A24: 2 | B24: Sablon T-Shirt | D24: 1 | E24: Pcs | G24: VML | H24: 1500 | J24: =D24*H24 -> 1500
A25: 3 | B25: Jahit T-Shirt | D25: 1 | E25: Pcs | G25: VML | H25: 2500 | J25: =D25*H25 -> 2500
A26: 4 | B26: QC T-Shirt | D26: 1 | E26: Pcs | G26: VML | H26: 2000 | J26: =D26*H26 -> 2000

Sheet 5. T-Shirt Oversize Combed Prem
B2: T-Shirt Oversize Combed Premium - Sablon | C2: Total Harga/Pcs
B3: Bahan | C3: =SUM(J10:J11) -> 39951.429
B4: Aksesoris | C4: =SUM(J14:J20) -> 4078.7
B5: Pekerja | C5: =SUM(J23:J26) -> 7250
B6: Total Biaya Per Pcs | C6: =SUM(C3:D5) -> 51280.129
A8: BAHAN UTAMA
A9: NO | B9: BAHAN | C9: WARNA | D9: PEMAKAIAN | E9: UNIT | F9: KETERANGAN Pemakaian | G9: VENDOR | H9: HARGA ECER | I9: HARGA ROLL | J9: HARGA / PCS
A10: 1 | B10: Cotton Combed Premium | C10: Hitam | D10: =1/3.5 -> 0.28571429 | E10: Kg | F10: 1 kg untuk 3,5 Pcs | G10: CV. Terang Mulia Bandung | H10: 135000 | J10: =D10*H10 -> 38571.429
A11: 2 | B11: Rib Cotton Combed Premium | C11: Hitam | D11: =1/100 -> 0.01 | E11: Kg | F11: 1 Kg untuk 100 Pcs | G11: CV. Terang Mulia Bandung | H11: 138000 | J11: =D11*H11 -> 1380
A12: AKSESORIS
A13: NO | B13: BAHAN | C13: WARNA | D13: PEMAKAIAN | E13: UNIT | F13: KET. PEMAKAIAN | G13: VENDOR | H13: HARGA ECER | I13: HARGA ROLL | J13: HARGA / PCS
A14: 1 | B14: Benang Jahit | C14: Hitam | D14: =4/100 -> 0.04 | E14: Lusin | F14: 1 lusin jadi 100pc | G14: Toko 1001 | H14: 25000 | J14: =D14*H14 -> 1000
A15: 2 | B15: Benang Obras | C15: Hitam | D15: 0 | E15: Cones | F15: 4 cones jadi 120pc | G15: Toko 1001 | H15: 13000 | J15: =D15*H15 -> 0
A16: 3 | B16: Label Size Bordir | C16: Hitam | D16: =1/100 -> 0.01 | E16: Golong | F16: 1 Golong Jadi 100 pc | G16: Toko 1001 | H16: 10000 | J16: =D16*H16 -> 100
A17: 4 | B17: Plastik Opp 30 Micron | C17: Bening | D17: 1 | E17: Pcs | F17: 1 Plastik 1 Pcs | G17: Mapan Plastik | H17: 370 | J17: =D17*H17 -> 370
A18: 5 | B18: Plastik Pp 50x60cm | C18: Bening | D18: =1/10 -> 0.1 | E18: Pcs | F18: 1 Plastik 10 Pcs | G18: Istana Plastik | H18: 587 | J18: =D18*H18 -> 58.7
A19: 6 | B19: Karung | C19: Putih | D19: =1/100 -> 0.01 | E19: Pcs | F19: 1 karung 100 pcs | G19: Cibadak | H19: 5000 | J19: =D19*H19 -> 50
A20: 7 | B20: Cat Sablon Plastisol | C20: Mix Warna | D20: 1 | E20: Pcs | F20: - | G20: Metro SPS | H20: 2500 | J20: =D20*H20 -> 2500
A21: Manufaktur
A22: NO | B22: WORK | D22: PEMAKAIAN | E22: UNIT | F22: KET. PEMAKAIAN | G22: VENDOR | H22: ESTIMASI MIN | J22: HARGA / PCS
A23: 1 | B23: Cutting T-Shirt | D23: 1 | E23: Pcs | G23: VML | H23: 750 | J23: =D23*H23 -> 750
A24: 2 | B24: Sablon T-Shirt | D24: 1 | E24: Pcs | G24: VML | H24: 2000 | J24: =D24*H24 -> 2000
A25: 3 | B25: Jahit T-Shirt | D25: 1 | E25: Pcs | G25: VML | H25: 2500 | J25: =D25*H25 -> 2500
A26: 4 | B26: QC T-Shirt | D26: 1 | E26: Pcs | G26: VML | H26: 2000 | J26: =D26*H26 -> 2000

Sheet 6. T-Shirt Oversize Combed Regu
B2: T-Shirt Oversize Combed Reguler - Sablon | C2: Total Harga/Pcs
B3: Bahan | C3: =SUM(J10:J11) -> 34402.857
B4: Aksesoris | C4: =SUM(J14:J20) -> 4078.7
B5: Pekerja | C5: =SUM(J23:J26) -> 7250
B6: Total Biaya Per Pcs | C6: =SUM(C3:D5) -> 45731.557
A8: BAHAN UTAMA
A9: NO | B9: BAHAN | C9: WARNA | D9: PEMAKAIAN | E9: UNIT | F9: KETERANGAN Pemakaian | G9: VENDOR | H9: HARGA ECER | I9: HARGA ROLL | J9: HARGA / PCS
A10: 1 | B10: Cotton Combed Reguler | C10: Hitam | D10: =1/3.5 -> 0.28571429 | E10: Kg | F10: 1 kg untuk 3,5 Pcs | G10: Fokus | H10: 116000 | J10: =D10*H10 -> 33142.857
A11: 2 | B11: Rib Cotton Combed Reguler | C11: Hitam | D11: =1/100 -> 0.01 | E11: Kg | F11: 1 Kg untuk 100 Pcs | G11: Fokus | H11: 126000 | J11: =D11*H11 -> 1260
A12: AKSESORIS
A13: NO | B13: BAHAN | C13: WARNA | D13: PEMAKAIAN | E13: UNIT | F13: KET. PEMAKAIAN | G13: VENDOR | H13: HARGA ECER | I13: HARGA ROLL | J13: HARGA / PCS
A14: 1 | B14: Benang Jahit | C14: Hitam | D14: =4/100 -> 0.04 | E14: Lusin | F14: 1 lusin jadi 100pc | G14: Toko 1001 | H14: 25000 | J14: =D14*H14 -> 1000
A15: 2 | B15: Benang Obras | C15: Hitam | D15: 0 | E15: Cones | F15: 4 cones jadi 120pc | G15: Toko 1001 | H15: 13000 | J15: =D15*H15 -> 0
A16: 3 | B16: Label Size Bordir | C16: Hitam | D16: =1/100 -> 0.01 | E16: Golong | F16: 1 Golong Jadi 100 pc | G16: Toko 1001 | H16: 10000 | J16: =D16*H16 -> 100
A17: 4 | B17: Plastik Opp 30 Micron | C17: Bening | D17: 1 | E17: Pcs | F17: 1 Plastik 1 Pcs | G17: Mapan Plastik | H17: 370 | J17: =D17*H17 -> 370
A18: 5 | B18: Plastik Pp 50x60cm | C18: Bening | D18: =1/10 -> 0.1 | E18: Pcs | F18: 1 Plastik 10 Pcs | G18: Istana Plastik | H18: 587 | J18: =D18*H18 -> 58.7
A19: 6 | B19: Karung | C19: Putih | D19: =1/100 -> 0.01 | E19: Pcs | F19: 1 karung 100 pcs | G19: Cibadak | H19: 5000 | J19: =D19*H19 -> 50
A20: 7 | B20: Cat Sablon Plastisol | C20: Mix Warna | D20: 1 | E20: Pcs | F20: - | G20: Metro SPS | H20: 2500 | J20: =D20*H20 -> 2500
A21: Manufaktur
A22: NO | B22: WORK | D22: PEMAKAIAN | E22: UNIT | F22: KET. PEMAKAIAN | G22: VENDOR | H22: ESTIMASI MIN | J22: HARGA / PCS
A23: 1 | B23: Cutting T-Shirt | D23: 1 | E23: Pcs | G23: VML | H23: 750 | J23: =D23*H23 -> 750
A24: 2 | B24: Sablon T-Shirt | D24: 1 | E24: Pcs | G24: VML | H24: 2000 | J24: =D24*H24 -> 2000
A25: 3 | B25: Jahit T-Shirt | D25: 1 | E25: Pcs | G25: VML | H25: 2500 | J25: =D25*H25 -> 2500
A26: 4 | B26: QC T-Shirt | D26: 1 | E26: Pcs | G26: VML | H26: 2000 | J26: =D26*H26 -> 2000

Sheet 7. T-Shirt Oversize Combed Prem
B2: T-Shirt Oversize Combed Premium - DTF | C2: Total Harga/Pcs
B3: Bahan | C3: =SUM(J10:J11) -> 39951.429
B4: Aksesoris | C4: =SUM(J14:J20) -> 5328.7
B5: Pekerja | C5: =SUM(J23:J26) -> 7250
B6: Total Biaya Per Pcs | C6: =SUM(C3:D5) -> 52530.129
A8: BAHAN UTAMA
A9: NO | B9: BAHAN | C9: WARNA | D9: PEMAKAIAN | E9: UNIT | F9: KETERANGAN Pemakaian | G9: VENDOR | H9: HARGA ECER | I9: HARGA ROLL | J9: HARGA / PCS
A10: 1 | B10: Cotton Combed Premium | C10: Hitam | D10: =1/3.5 -> 0.28571429 | E10: Kg | F10: 1 kg untuk 3,5 Pcs | G10: CV. Terang Mulia Bandung | H10: 135000 | J10: =D10*H10 -> 38571.429
A11: 2 | B11: Rib Cotton Combed Premium | C11: Hitam | D11: =1/100 -> 0.01 | E11: Kg | F11: 1 Kg untuk 100 Pcs | G11: CV. Terang Mulia Bandung | H11: 138000 | J11: =D11*H11 -> 1380
A12: AKSESORIS
A13: NO | B13: BAHAN | C13: WARNA | D13: PEMAKAIAN | E13: UNIT | F13: KET. PEMAKAIAN | G13: VENDOR | H13: HARGA ECER | I13: HARGA ROLL | J13: HARGA / PCS
A14: 1 | B14: Benang Jahit | C14: Hitam | D14: =4/100 -> 0.04 | E14: Lusin | F14: 1 lusin jadi 100pc | G14: Toko 1001 | H14: 25000 | J14: =D14*H14 -> 1000
A15: 2 | B15: Benang Obras | C15: Hitam | D15: 0 | E15: Cones | F15: 4 cones jadi 120pc | G15: Toko 1001 | H15: 13000 | J15: =D15*H15 -> 0
A16: 3 | B16: Label Size Bordir | C16: Hitam | D16: =1/100 -> 0.01 | E16: Golong | F16: 1 Golong Jadi 100 pc | G16: Toko 1001 | H16: 10000 | J16: =D16*H16 -> 100
A17: 4 | B17: Plastik Opp 30 Micron | C17: Bening | D17: 1 | E17: Pcs | F17: 1 Plastik 1 Pcs | G17: Mapan Plastik | H17: 370 | J17: =D17*H17 -> 370
A18: 5 | B18: Plastik Pp 50x60cm | C18: Bening | D18: =1/10 -> 0.1 | E18: Pcs | F18: 1 Plastik 10 Pcs | G18: Istana Plastik | H18: 587 | J18: =D18*H18 -> 58.7
A19: 6 | B19: Karung | C19: Putih | D19: =1/100 -> 0.01 | E19: Pcs | F19: 1 karung 100 pcs | G19: Cibadak | H19: 5000 | J19: =D19*H19 -> 50
A20: 7 | B20: DTF | C20: Mix Warna | D20: 1 | E20: Pcs | F20: - | G20: Max Print | H20: 3750 | J20: =D20*H20 -> 3750
A21: Manufaktur
A22: NO | B22: WORK | D22: PEMAKAIAN | E22: UNIT | F22: KET. PEMAKAIAN | G22: VENDOR | H22: ESTIMASI MIN | J22: HARGA / PCS
A23: 1 | B23: Cutting T-Shirt | D23: 1 | E23: Pcs | G23: VML | H23: 750 | J23: =D23*H23 -> 750
A24: 2 | B24: Sablon T-Shirt | D24: 1 | E24: Pcs | G24: VML | H24: 2000 | J24: =D24*H24 -> 2000
A25: 3 | B25: Jahit T-Shirt | D25: 1 | E25: Pcs | G25: VML | H25: 2500 | J25: =D25*H25 -> 2500
A26: 4 | B26: QC T-Shirt | D26: 1 | E26: Pcs | G26: VML | H26: 2000 | J26: =D26*H26 -> 2000

Sheet 8. T-Shirt Oversize Combed Regu
B2: T-Shirt Oversize Combed Reguler - DTF | C2: Total Harga/Pcs
B3: Bahan | C3: =SUM(J10:J11) -> 34402.857
B4: Aksesoris | C4: =SUM(J14:J20) -> 5328.7
B5: Pekerja | C5: =SUM(J23:J26) -> 7250
B6: Total Biaya Per Pcs | C6: =SUM(C3:D5) -> 46981.557
A8: BAHAN UTAMA
A9: NO | B9: BAHAN | C9: WARNA | D9: PEMAKAIAN | E9: UNIT | F9: KETERANGAN Pemakaian | G9: VENDOR | H9: HARGA ECER | I9: HARGA ROLL | J9: HARGA / PCS
A10: 1 | B10: Cotton Combed Reguler | C10: Hitam | D10: =1/3.5 -> 0.28571429 | E10: Kg | F10: 1 kg untuk 3,5 Pcs | G10: Fokus | H10: 116000 | J10: =D10*H10 -> 33142.857
A11: 2 | B11: Rib Cotton Combed Reguler | C11: Hitam | D11: =1/100 -> 0.01 | E11: Kg | F11: 1 Kg untuk 100 Pcs | G11: Fokus | H11: 126000 | J11: =D11*H11 -> 1260
A12: AKSESORIS
A13: NO | B13: BAHAN | C13: WARNA | D13: PEMAKAIAN | E13: UNIT | F13: KET. PEMAKAIAN | G13: VENDOR | H13: HARGA ECER | I13: HARGA ROLL | J13: HARGA / PCS
A14: 1 | B14: Benang Jahit | C14: Hitam | D14: =4/100 -> 0.04 | E14: Lusin | F14: 1 lusin jadi 100pc | G14: Toko 1001 | H14: 25000 | J14: =D14*H14 -> 1000
A15: 2 | B15: Benang Obras | C15: Hitam | D15: 0 | E15: Cones | F15: 4 cones jadi 120pc | G15: Toko 1001 | H15: 13000 | J15: =D15*H15 -> 0
A16: 3 | B16: Label Size Bordir | C16: Hitam | D16: =1/100 -> 0.01 | E16: Golong | F16: 1 Golong Jadi 100 pc | G16: Toko 1001 | H16: 10000 | J16: =D16*H16 -> 100
A17: 4 | B17: Plastik Opp 30 Micron | C17: Bening | D17: 1 | E17: Pcs | F17: 1 Plastik 1 Pcs | G17: Mapan Plastik | H17: 370 | J17: =D17*H17 -> 370
A18: 5 | B18: Plastik Pp 50x60cm | C18: Bening | D18: =1/10 -> 0.1 | E18: Pcs | F18: 1 Plastik 10 Pcs | G18: Istana Plastik | H18: 587 | J18: =D18*H18 -> 58.7
A19: 6 | B19: Karung | C19: Putih | D19: =1/100 -> 0.01 | E19: Pcs | F19: 1 karung 100 pcs | G19: Cibadak | H19: 5000 | J19: =D19*H19 -> 50
A20: 7 | B20: DTF | C20: Mix Warna | D20: 1 | E20: Pcs | F20: - | G20: Max Print | H20: 3750 | J20: =D20*H20 -> 3750
A21: Manufaktur
A22: NO | B22: WORK | D22: PEMAKAIAN | E22: UNIT | F22: KET. PEMAKAIAN | G22: VENDOR | H22: ESTIMASI MIN | J22: HARGA / PCS
A23: 1 | B23: Cutting T-Shirt | D23: 1 | E23: Pcs | G23: VML | H23: 750 | J23: =D23*H23 -> 750
A24: 2 | B24: Sablon T-Shirt | D24: 1 | E24: Pcs | G24: VML | H24: 2000 | J24: =D24*H24 -> 2000
A25: 3 | B25: Jahit T-Shirt | D25: 1 | E25: Pcs | G25: VML | H25: 2500 | J25: =D25*H25 -> 2500
A26: 4 | B26: QC T-Shirt | D26: 1 | E26: Pcs | G26: VML | H26: 2000 | J26: =D26*H26 -> 2000

Sheet 9. T-Shirt Boxy Combed Premium 
B2: T-Shirt Boxy Combed Premium - Sablon | C2: Total Harga/Pcs
B3: Bahan | C3: =SUM(J10:J11) -> 39951.429
B4: Aksesoris | C4: =SUM(J14:J20) -> 4078.7
B5: Pekerja | C5: =SUM(J23:J26) -> 7250
B6: Total Biaya Per Pcs | C6: =SUM(C3:D5) -> 51280.129
A8: BAHAN UTAMA
A9: NO | B9: BAHAN | C9: WARNA | D9: PEMAKAIAN | E9: UNIT | F9: KETERANGAN Pemakaian | G9: VENDOR | H9: HARGA ECER | I9: HARGA ROLL | J9: HARGA / PCS
A10: 1 | B10: Cotton Combed Premium | C10: Hitam | D10: =1/3.5 -> 0.28571429 | E10: Kg | F10: 1 kg untuk 3,5 Pcs | G10: CV. Terang Mulia Bandung | H10: 135000 | J10: =D10*H10 -> 38571.429
A11: 2 | B11: Rib Cotton Combed Premium | C11: Hitam | D11: =1/100 -> 0.01 | E11: Kg | F11: 1 Kg untuk 100 Pcs | G11: CV. Terang Mulia Bandung | H11: 138000 | J11: =D11*H11 -> 1380
A12: AKSESORIS
A13: NO | B13: BAHAN | C13: WARNA | D13: PEMAKAIAN | E13: UNIT | F13: KET. PEMAKAIAN | G13: VENDOR | H13: HARGA ECER | I13: HARGA ROLL | J13: HARGA / PCS
A14: 1 | B14: Benang Jahit | C14: Hitam | D14: =4/100 -> 0.04 | E14: Lusin | F14: 1 lusin jadi 100pc | G14: Toko 1001 | H14: 25000 | J14: =D14*H14 -> 1000
A15: 2 | B15: Benang Obras | C15: Hitam | D15: 0 | E15: Cones | F15: 4 cones jadi 120pc | G15: Toko 1001 | H15: 13000 | J15: =D15*H15 -> 0
A16: 3 | B16: Label Size Bordir | C16: Hitam | D16: =1/100 -> 0.01 | E16: Golong | F16: 1 Golong Jadi 100 pc | G16: Toko 1001 | H16: 10000 | J16: =D16*H16 -> 100
A17: 4 | B17: Plastik Opp 30 Micron | C17: Bening | D17: 1 | E17: Pcs | F17: 1 Plastik 1 Pcs | G17: Mapan Plastik | H17: 370 | J17: =D17*H17 -> 370
A18: 5 | B18: Plastik Pp 50x60cm | C18: Bening | D18: =1/10 -> 0.1 | E18: Pcs | F18: 1 Plastik 10 Pcs | G18: Istana Plastik | H18: 587 | J18: =D18*H18 -> 58.7
A19: 6 | B19: Karung | C19: Putih | D19: =1/100 -> 0.01 | E19: Pcs | F19: 1 karung 100 pcs | G19: Cibadak | H19: 5000 | J19: =D19*H19 -> 50
A20: 7 | B20: Cat Sablon Plastisol | C20: Mix Warna | D20: 1 | E20: Pcs | F20: - | G20: Metro SPS | H20: 2500 | J20: =D20*H20 -> 2500
A21: Manufaktur
A22: NO | B22: WORK | D22: PEMAKAIAN | E22: UNIT | F22: KET. PEMAKAIAN | G22: VENDOR | H22: ESTIMASI MIN | J22: HARGA / PCS
A23: 1 | B23: Cutting T-Shirt | D23: 1 | E23: Pcs | G23: VML | H23: 750 | J23: =D23*H23 -> 750
A24: 2 | B24: Sablon T-Shirt | D24: 1 | E24: Pcs | G24: VML | H24: 2000 | J24: =D24*H24 -> 2000
A25: 3 | B25: Jahit T-Shirt | D25: 1 | E25: Pcs | G25: VML | H25: 2500 | J25: =D25*H25 -> 2500
A26: 4 | B26: QC T-Shirt | D26: 1 | E26: Pcs | G26: VML | H26: 2000 | J26: =D26*H26 -> 2000

Sheet 10. T-Shirt Boxy Combed Reguler
B2: T-Shirt Boxy Combed Reguler - Sablon | C2: Total Harga/Pcs
B3: Bahan | C3: =SUM(J10:J11) -> 34402.857
B4: Aksesoris | C4: =SUM(J14:J20) -> 4078.7
B5: Pekerja | C5: =SUM(J23:J26) -> 7250
B6: Total Biaya Per Pcs | C6: =SUM(C3:D5) -> 45731.557
A8: BAHAN UTAMA
A9: NO | B9: BAHAN | C9: WARNA | D9: PEMAKAIAN | E9: UNIT | F9: KETERANGAN Pemakaian | G9: VENDOR | H9: HARGA ECER | I9: HARGA ROLL | J9: HARGA / PCS
A10: 1 | B10: Cotton Combed Premium | C10: Hitam | D10: =1/3.5 -> 0.28571429 | E10: Kg | F10: 1 kg untuk 3,5 Pcs | G10: Fokus | H10: 116000 | J10: =D10*H10 -> 33142.857
A11: 2 | B11: Rib Cotton Combed Premium | C11: Hitam | D11: =1/100 -> 0.01 | E11: Kg | F11: 1 Kg untuk 100 Pcs | G11: Fokus | H11: 126000 | J11: =D11*H11 -> 1260
A12: AKSESORIS
A13: NO | B13: BAHAN | C13: WARNA | D13: PEMAKAIAN | E13: UNIT | F13: KET. PEMAKAIAN | G13: VENDOR | H13: HARGA ECER | I13: HARGA ROLL | J13: HARGA / PCS
A14: 1 | B14: Benang Jahit | C14: Hitam | D14: =4/100 -> 0.04 | E14: Lusin | F14: 1 lusin jadi 100pc | G14: Toko 1001 | H14: 25000 | J14: =D14*H14 -> 1000
A15: 2 | B15: Benang Obras | C15: Hitam | D15: 0 | E15: Cones | F15: 4 cones jadi 120pc | G15: Toko 1001 | H15: 13000 | J15: =D15*H15 -> 0
A16: 3 | B16: Label Size Bordir | C16: Hitam | D16: =1/100 -> 0.01 | E16: Golong | F16: 1 Golong Jadi 100 pc | G16: Toko 1001 | H16: 10000 | J16: =D16*H16 -> 100
A17: 4 | B17: Plastik Opp 30 Micron | C17: Bening | D17: 1 | E17: Pcs | F17: 1 Plastik 1 Pcs | G17: Mapan Plastik | H17: 370 | J17: =D17*H17 -> 370
A18: 5 | B18: Plastik Pp 50x60cm | C18: Bening | D18: =1/10 -> 0.1 | E18: Pcs | F18: 1 Plastik 10 Pcs | G18: Istana Plastik | H18: 587 | J18: =D18*H18 -> 58.7
A19: 6 | B19: Karung | C19: Putih | D19: =1/100 -> 0.01 | E19: Pcs | F19: 1 karung 100 pcs | G19: Cibadak | H19: 5000 | J19: =D19*H19 -> 50
A20: 7 | B20: Cat Sablon Plastisol | C20: Mix Warna | D20: 1 | E20: Pcs | F20: - | G20: Metro SPS | H20: 2500 | J20: =D20*H20 -> 2500
A21: Manufaktur
A22: NO | B22: WORK | D22: PEMAKAIAN | E22: UNIT | F22: KET. PEMAKAIAN | G22: VENDOR | H22: ESTIMASI MIN | J22: HARGA / PCS
A23: 1 | B23: Cutting T-Shirt | D23: 1 | E23: Pcs | G23: VML | H23: 750 | J23: =D23*H23 -> 750
A24: 2 | B24: Sablon T-Shirt | D24: 1 | E24: Pcs | G24: VML | H24: 2000 | J24: =D24*H24 -> 2000
A25: 3 | B25: Jahit T-Shirt | D25: 1 | E25: Pcs | G25: VML | H25: 2500 | J25: =D25*H25 -> 2500
A26: 4 | B26: QC T-Shirt | D26: 1 | E26: Pcs | G26: VML | H26: 2000 | J26: =D26*H26 -> 2000

Sheet 11. T-Shirt Boxy Combed Premium
B2: T-Shirt Boxy Combed Premium - DTF | C2: Total Harga/Pcs
B3: Bahan | C3: =SUM(J10:J11) -> 39951.429
B4: Aksesoris | C4: =SUM(J14:J20) -> 5328.7
B5: Pekerja | C5: =SUM(J23:J26) -> 7250
B6: Total Biaya Per Pcs | C6: =SUM(C3:D5) -> 52530.129
A8: BAHAN UTAMA
A9: NO | B9: BAHAN | C9: WARNA | D9: PEMAKAIAN | E9: UNIT | F9: KETERANGAN Pemakaian | G9: VENDOR | H9: HARGA ECER | I9: HARGA ROLL | J9: HARGA / PCS
A10: 1 | B10: Cotton Combed Premium | C10: Hitam | D10: =1/3.5 -> 0.28571429 | E10: Kg | F10: 1 kg untuk 3,5 Pcs | G10: CV. Terang Mulia Bandung | H10: 135000 | J10: =D10*H10 -> 38571.429
A11: 2 | B11: Rib Cotton Combed Premium | C11: Hitam | D11: =1/100 -> 0.01 | E11: Kg | F11: 1 Kg untuk 100 Pcs | G11: CV. Terang Mulia Bandung | H11: 138000 | J11: =D11*H11 -> 1380
A12: AKSESORIS
A13: NO | B13: BAHAN | C13: WARNA | D13: PEMAKAIAN | E13: UNIT | F13: KET. PEMAKAIAN | G13: VENDOR | H13: HARGA ECER | I13: HARGA ROLL | J13: HARGA / PCS
A14: 1 | B14: Benang Jahit | C14: Hitam | D14: =4/100 -> 0.04 | E14: Lusin | F14: 1 lusin jadi 100pc | G14: Toko 1001 | H14: 25000 | J14: =D14*H14 -> 1000
A15: 2 | B15: Benang Obras | C15: Hitam | D15: 0 | E15: Cones | F15: 4 cones jadi 120pc | G15: Toko 1001 | H15: 13000 | J15: =D15*H15 -> 0
A16: 3 | B16: Label Size Bordir | C16: Hitam | D16: =1/100 -> 0.01 | E16: Golong | F16: 1 Golong Jadi 100 pc | G16: Toko 1001 | H16: 10000 | J16: =D16*H16 -> 100
A17: 4 | B17: Plastik Opp 30 Micron | C17: Bening | D17: 1 | E17: Pcs | F17: 1 Plastik 1 Pcs | G17: Mapan Plastik | H17: 370 | J17: =D17*H17 -> 370
A18: 5 | B18: Plastik Pp 50x60cm | C18: Bening | D18: =1/10 -> 0.1 | E18: Pcs | F18: 1 Plastik 10 Pcs | G18: Istana Plastik | H18: 587 | J18: =D18*H18 -> 58.7
A19: 6 | B19: Karung | C19: Putih | D19: =1/100 -> 0.01 | E19: Pcs | F19: 1 karung 100 pcs | G19: Cibadak | H19: 5000 | J19: =D19*H19 -> 50
A20: 7 | B20: DTF | C20: Mix Warna | D20: 1 | E20: Pcs | F20: - | G20: Max Print | H20: 3750 | J20: =D20*H20 -> 3750
A21: Manufaktur
A22: NO | B22: WORK | D22: PEMAKAIAN | E22: UNIT | F22: KET. PEMAKAIAN | G22: VENDOR | H22: ESTIMASI MIN | J22: HARGA / PCS
A23: 1 | B23: Cutting T-Shirt | D23: 1 | E23: Pcs | G23: VML | H23: 750 | J23: =D23*H23 -> 750
A24: 2 | B24: Sablon T-Shirt | D24: 1 | E24: Pcs | G24: VML | H24: 2000 | J24: =D24*H24 -> 2000
A25: 3 | B25: Jahit T-Shirt | D25: 1 | E25: Pcs | G25: VML | H25: 2500 | J25: =D25*H25 -> 2500
A26: 4 | B26: QC T-Shirt | D26: 1 | E26: Pcs | G26: VML | H26: 2000 | J26: =D26*H26 -> 2000

Sheet 12. T-Shirt Boxy Combed Reguler
B2: T-Shirt Boxy Combed Reguler - DTF | C2: Total Harga/Pcs
B3: Bahan | C3: =SUM(J10:J11) -> 34402.857
B4: Aksesoris | C4: =SUM(J14:J20) -> 5328.7
B5: Pekerja | C5: =SUM(J23:J26) -> 7250
B6: Total Biaya Per Pcs | C6: =SUM(C3:D5) -> 46981.557
A8: BAHAN UTAMA
A9: NO | B9: BAHAN | C9: WARNA | D9: PEMAKAIAN | E9: UNIT | F9: KETERANGAN Pemakaian | G9: VENDOR | H9: HARGA ECER | I9: HARGA ROLL | J9: HARGA / PCS
A10: 1 | B10: Cotton Combed Premium | C10: Hitam | D10: =1/3.5 -> 0.28571429 | E10: Kg | F10: 1 kg untuk 3,5 Pcs | G10: Fokus | H10: 116000 | J10: =D10*H10 -> 33142.857
A11: 2 | B11: Rib Cotton Combed Premium | C11: Hitam | D11: =1/100 -> 0.01 | E11: Kg | F11: 1 Kg untuk 100 Pcs | G11: Fokus | H11: 126000 | J11: =D11*H11 -> 1260
A12: AKSESORIS
A13: NO | B13: BAHAN | C13: WARNA | D13: PEMAKAIAN | E13: UNIT | F13: KET. PEMAKAIAN | G13: VENDOR | H13: HARGA ECER | I13: HARGA ROLL | J13: HARGA / PCS
A14: 1 | B14: Benang Jahit | C14: Hitam | D14: =4/100 -> 0.04 | E14: Lusin | F14: 1 lusin jadi 100pc | G14: Toko 1001 | H14: 25000 | J14: =D14*H14 -> 1000
A15: 2 | B15: Benang Obras | C15: Hitam | D15: 0 | E15: Cones | F15: 4 cones jadi 120pc | G15: Toko 1001 | H15: 13000 | J15: =D15*H15 -> 0
A16: 3 | B16: Label Size Bordir | C16: Hitam | D16: =1/100 -> 0.01 | E16: Golong | F16: 1 Golong Jadi 100 pc | G16: Toko 1001 | H16: 10000 | J16: =D16*H16 -> 100
A17: 4 | B17: Plastik Opp 30 Micron | C17: Bening | D17: 1 | E17: Pcs | F17: 1 Plastik 1 Pcs | G17: Mapan Plastik | H17: 370 | J17: =D17*H17 -> 370
A18: 5 | B18: Plastik Pp 50x60cm | C18: Bening | D18: =1/10 -> 0.1 | E18: Pcs | F18: 1 Plastik 10 Pcs | G18: Istana Plastik | H18: 587 | J18: =D18*H18 -> 58.7
A19: 6 | B19: Karung | C19: Putih | D19: =1/100 -> 0.01 | E19: Pcs | F19: 1 karung 100 pcs | G19: Cibadak | H19: 5000 | J19: =D19*H19 -> 50
A20: 7 | B20: DTF | C20: Mix Warna | D20: 1 | E20: Pcs | F20: - | G20: Max Print | H20: 3750 | J20: =D20*H20 -> 3750
A21: Manufaktur
A22: NO | B22: WORK | D22: PEMAKAIAN | E22: UNIT | F22: KET. PEMAKAIAN | G22: VENDOR | H22: ESTIMASI MIN | J22: HARGA / PCS
A23: 1 | B23: Cutting T-Shirt | D23: 1 | E23: Pcs | G23: VML | H23: 750 | J23: =D23*H23 -> 750
A24: 2 | B24: Sablon T-Shirt | D24: 1 | E24: Pcs | G24: VML | H24: 2000 | J24: =D24*H24 -> 2000
A25: 3 | B25: Jahit T-Shirt | D25: 1 | E25: Pcs | G25: VML | H25: 2500 | J25: =D25*H25 -> 2500
A26: 4 | B26: QC T-Shirt | D26: 1 | E26: Pcs | G26: VML | H26: 2000 | J26: =D26*H26 -> 2000

Sheet 13. T-Shirt US Combed Premium -
B2: T-Shirt US Combed Premium - Sablon | C2: Total Harga/Pcs
B3: Bahan | C3: =SUM(J10:J11) -> 39951.429
B4: Aksesoris | C4: =SUM(J14:J20) -> 4078.7
B5: Pekerja | C5: =SUM(J23:J26) -> 7250
B6: Total Biaya Per Pcs | C6: =SUM(C3:D5) -> 51280.129
A8: BAHAN UTAMA
A9: NO | B9: BAHAN | C9: WARNA | D9: PEMAKAIAN | E9: UNIT | F9: KETERANGAN Pemakaian | G9: VENDOR | H9: HARGA ECER | I9: HARGA ROLL | J9: HARGA / PCS
A10: 1 | B10: Cotton Combed Premium | C10: Hitam | D10: =1/3.5 -> 0.28571429 | E10: Kg | F10: 1 kg untuk 3,5 Pcs | G10: CV. Terang Mulia Bandung | H10: 135000 | J10: =D10*H10 -> 38571.429
A11: 2 | B11: Rib Cotton Combed Premium | C11: Hitam | D11: =1/100 -> 0.01 | E11: Kg | F11: 1 Kg untuk 100 Pcs | G11: CV. Terang Mulia Bandung | H11: 138000 | J11: =D11*H11 -> 1380
A12: AKSESORIS
A13: NO | B13: BAHAN | C13: WARNA | D13: PEMAKAIAN | E13: UNIT | F13: KET. PEMAKAIAN | G13: VENDOR | H13: HARGA ECER | I13: HARGA ROLL | J13: HARGA / PCS
A14: 1 | B14: Benang Jahit | C14: Hitam | D14: =4/100 -> 0.04 | E14: Lusin | F14: 1 lusin jadi 100pc | G14: Toko 1001 | H14: 25000 | J14: =D14*H14 -> 1000
A15: 2 | B15: Benang Obras | C15: Hitam | D15: 0 | E15: Cones | F15: 4 cones jadi 120pc | G15: Toko 1001 | H15: 13000 | J15: =D15*H15 -> 0
A16: 3 | B16: Label Size Bordir | C16: Hitam | D16: =1/100 -> 0.01 | E16: Golong | F16: 1 Golong Jadi 100 pc | G16: Toko 1001 | H16: 10000 | J16: =D16*H16 -> 100
A17: 4 | B17: Plastik Opp 30 Micron | C17: Bening | D17: 1 | E17: Pcs | F17: 1 Plastik 1 Pcs | G17: Mapan Plastik | H17: 370 | J17: =D17*H17 -> 370
A18: 5 | B18: Plastik Pp 50x60cm | C18: Bening | D18: =1/10 -> 0.1 | E18: Pcs | F18: 1 Plastik 10 Pcs | G18: Istana Plastik | H18: 587 | J18: =D18*H18 -> 58.7
A19: 6 | B19: Karung | C19: Putih | D19: =1/100 -> 0.01 | E19: Pcs | F19: 1 karung 100 pcs | G19: Cibadak | H19: 5000 | J19: =D19*H19 -> 50
A20: 7 | B20: Cat Sablon Plastisol | C20: Mix Warna | D20: 1 | E20: Pcs | F20: - | G20: Metro SPS | H20: 2500 | J20: =D20*H20 -> 2500
A21: Manufaktur
A22: NO | B22: WORK | D22: PEMAKAIAN | E22: UNIT | F22: KET. PEMAKAIAN | G22: VENDOR | H22: ESTIMASI MIN | J22: HARGA / PCS
A23: 1 | B23: Cutting T-Shirt | D23: 1 | E23: Pcs | G23: VML | H23: 750 | J23: =D23*H23 -> 750
A24: 2 | B24: Sablon T-Shirt | D24: 1 | E24: Pcs | G24: VML | H24: 2000 | J24: =D24*H24 -> 2000
A25: 3 | B25: Jahit T-Shirt | D25: 1 | E25: Pcs | G25: VML | H25: 2500 | J25: =D25*H25 -> 2500
A26: 4 | B26: QC T-Shirt | D26: 1 | E26: Pcs | G26: VML | H26: 2000 | J26: =D26*H26 -> 2000

Sheet 14. T-Shirt US Combed Reguler -
B2: T-Shirt US Combed Reguler - Sablon | C2: Total Harga/Pcs
B3: Bahan | C3: =SUM(J10:J11) -> 31786.316
B4: Aksesoris | C4: =SUM(J14:J20) -> 4078.7
B5: Pekerja | C5: =SUM(J23:J26) -> 7250
B6: Total Biaya Per Pcs | C6: =SUM(C3:D5) -> 43115.016
A8: BAHAN UTAMA
A9: NO | B9: BAHAN | C9: WARNA | D9: PEMAKAIAN | E9: UNIT | F9: KETERANGAN Pemakaian | G9: VENDOR | H9: HARGA ECER | I9: HARGA ROLL | J9: HARGA / PCS
A10: 1 | B10: Cotton Combed Premium | C10: Hitam | D10: =1/3.8 -> 0.26315789 | E10: Kg | F10: 1 kg untuk 3,8 Pcs | G10: Fokus | H10: 116000 | J10: =D10*H10 -> 30526.316
A11: 2 | B11: Rib Cotton Combed Premium | C11: Hitam | D11: =1/100 -> 0.01 | E11: Kg | F11: 1 Kg untuk 100 Pcs | G11: Fokus | H11: 126000 | J11: =D11*H11 -> 1260
A12: AKSESORIS
A13: NO | B13: BAHAN | C13: WARNA | D13: PEMAKAIAN | E13: UNIT | F13: KET. PEMAKAIAN | G13: VENDOR | H13: HARGA ECER | I13: HARGA ROLL | J13: HARGA / PCS
A14: 1 | B14: Benang Jahit | C14: Hitam | D14: =4/100 -> 0.04 | E14: Lusin | F14: 1 lusin jadi 100pc | G14: Toko 1001 | H14: 25000 | J14: =D14*H14 -> 1000
A15: 2 | B15: Benang Obras | C15: Hitam | D15: 0 | E15: Cones | F15: 4 cones jadi 120pc | G15: Toko 1001 | H15: 13000 | J15: =D15*H15 -> 0
A16: 3 | B16: Label Size Bordir | C16: Hitam | D16: =1/100 -> 0.01 | E16: Golong | F16: 1 Golong Jadi 100 pc | G16: Toko 1001 | H16: 10000 | J16: =D16*H16 -> 100
A17: 4 | B17: Plastik Opp 30 Micron | C17: Bening | D17: 1 | E17: Pcs | F17: 1 Plastik 1 Pcs | G17: Mapan Plastik | H17: 370 | J17: =D17*H17 -> 370
A18: 5 | B18: Plastik Pp 50x60cm | C18: Bening | D18: =1/10 -> 0.1 | E18: Pcs | F18: 1 Plastik 10 Pcs | G18: Istana Plastik | H18: 587 | J18: =D18*H18 -> 58.7
A19: 6 | B19: Karung | C19: Putih | D19: =1/100 -> 0.01 | E19: Pcs | F19: 1 karung 100 pcs | G19: Cibadak | H19: 5000 | J19: =D19*H19 -> 50
A20: 7 | B20: Cat Sablon Plastisol | C20: Mix Warna | D20: 1 | E20: Pcs | F20: - | G20: Metro SPS | H20: 2500 | J20: =D20*H20 -> 2500
A21: Manufaktur
A22: NO | B22: WORK | D22: PEMAKAIAN | E22: UNIT | F22: KET. PEMAKAIAN | G22: VENDOR | H22: ESTIMASI MIN | J22: HARGA / PCS
A23: 1 | B23: Cutting T-Shirt | D23: 1 | E23: Pcs | G23: VML | H23: 750 | J23: =D23*H23 -> 750
A24: 2 | B24: Sablon T-Shirt | D24: 1 | E24: Pcs | G24: VML | H24: 2000 | J24: =D24*H24 -> 2000
A25: 3 | B25: Jahit T-Shirt | D25: 1 | E25: Pcs | G25: VML | H25: 2500 | J25: =D25*H25 -> 2500
A26: 4 | B26: QC T-Shirt | D26: 1 | E26: Pcs | G26: VML | H26: 2000 | J26: =D26*H26 -> 2000

Sheet 15. T-Shirt US Combed Premium -
B2: T-Shirt US Combed Premium - DTF | C2: Total Harga/Pcs
B3: Bahan | C3: =SUM(J10:J11) -> 36906.316
B4: Aksesoris | C4: =SUM(J14:J20) -> 5328.7
B5: Pekerja | C5: =SUM(J23:J26) -> 7250
B6: Total Biaya Per Pcs | C6: =SUM(C3:D5) -> 49485.016
A8: BAHAN UTAMA
A9: NO | B9: BAHAN | C9: WARNA | D9: PEMAKAIAN | E9: UNIT | F9: KETERANGAN Pemakaian | G9: VENDOR | H9: HARGA ECER | I9: HARGA ROLL | J9: HARGA / PCS
A10: 1 | B10: Cotton Combed Premium | C10: Hitam | D10: =1/3.8 -> 0.26315789 | E10: Kg | F10: 1 kg untuk 3,8 Pcs | G10: CV. Terang Mulia Bandung | H10: 135000 | J10: =D10*H10 -> 35526.316
A11: 2 | B11: Rib Cotton Combed Premium | C11: Hitam | D11: =1/100 -> 0.01 | E11: Kg | F11: 1 Kg untuk 100 Pcs | G11: CV. Terang Mulia Bandung | H11: 138000 | J11: =D11*H11 -> 1380
A12: AKSESORIS
A13: NO | B13: BAHAN | C13: WARNA | D13: PEMAKAIAN | E13: UNIT | F13: KET. PEMAKAIAN | G13: VENDOR | H13: HARGA ECER | I13: HARGA ROLL | J13: HARGA / PCS
A14: 1 | B14: Benang Jahit | C14: Hitam | D14: =4/100 -> 0.04 | E14: Lusin | F14: 1 lusin jadi 100pc | G14: Toko 1001 | H14: 25000 | J14: =D14*H14 -> 1000
A15: 2 | B15: Benang Obras | C15: Hitam | D15: 0 | E15: Cones | F15: 4 cones jadi 120pc | G15: Toko 1001 | H15: 13000 | J15: =D15*H15 -> 0
A16: 3 | B16: Label Size Bordir | C16: Hitam | D16: =1/100 -> 0.01 | E16: Golong | F16: 1 Golong Jadi 100 pc | G16: Toko 1001 | H16: 10000 | J16: =D16*H16 -> 100
A17: 4 | B17: Plastik Opp 30 Micron | C17: Bening | D17: 1 | E17: Pcs | F17: 1 Plastik 1 Pcs | G17: Mapan Plastik | H17: 370 | J17: =D17*H17 -> 370
A18: 5 | B18: Plastik Pp 50x60cm | C18: Bening | D18: =1/10 -> 0.1 | E18: Pcs | F18: 1 Plastik 10 Pcs | G18: Istana Plastik | H18: 587 | J18: =D18*H18 -> 58.7
A19: 6 | B19: Karung | C19: Putih | D19: =1/100 -> 0.01 | E19: Pcs | F19: 1 karung 100 pcs | G19: Cibadak | H19: 5000 | J19: =D19*H19 -> 50
A20: 7 | B20: DTF | C20: Mix Warna | D20: 1 | E20: Pcs | F20: - | G20: Max Print | H20: 3750 | J20: =D20*H20 -> 3750
A21: Manufaktur
A22: NO | B22: WORK | D22: PEMAKAIAN | E22: UNIT | F22: KET. PEMAKAIAN | G22: VENDOR | H22: ESTIMASI MIN | J22: HARGA / PCS
A23: 1 | B23: Cutting T-Shirt | D23: 1 | E23: Pcs | G23: VML | H23: 750 | J23: =D23*H23 -> 750
A24: 2 | B24: Sablon T-Shirt | D24: 1 | E24: Pcs | G24: VML | H24: 2000 | J24: =D24*H24 -> 2000
A25: 3 | B25: Jahit T-Shirt | D25: 1 | E25: Pcs | G25: VML | H25: 2500 | J25: =D25*H25 -> 2500
A26: 4 | B26: QC T-Shirt | D26: 1 | E26: Pcs | G26: VML | H26: 2000 | J26: =D26*H26 -> 2000

Sheet 16. T-Shirt US Combed Reguler -
B2: T-Shirt US Combed Reguler - DTF | C2: Total Harga/Pcs
B3: Bahan | C3: =SUM(J10:J11) -> 31786.316
B4: Aksesoris | C4: =SUM(J14:J20) -> 5328.7
B5: Pekerja | C5: =SUM(J23:J26) -> 7250
B6: Total Biaya Per Pcs | C6: =SUM(C3:D5) -> 44365.016
A8: BAHAN UTAMA
A9: NO | B9: BAHAN | C9: WARNA | D9: PEMAKAIAN | E9: UNIT | F9: KETERANGAN Pemakaian | G9: VENDOR | H9: HARGA ECER | I9: HARGA ROLL | J9: HARGA / PCS
A10: 1 | B10: Cotton Combed Premium | C10: Hitam | D10: =1/3.8 -> 0.26315789 | E10: Kg | F10: 1 kg untuk 3,8 Pcs | G10: Fokus | H10: 116000 | J10: =D10*H10 -> 30526.316
A11: 2 | B11: Rib Cotton Combed Premium | C11: Hitam | D11: =1/100 -> 0.01 | E11: Kg | F11: 1 Kg untuk 100 Pcs | G11: Fokus | H11: 126000 | J11: =D11*H11 -> 1260
A12: AKSESORIS
A13: NO | B13: BAHAN | C13: WARNA | D13: PEMAKAIAN | E13: UNIT | F13: KET. PEMAKAIAN | G13: VENDOR | H13: HARGA ECER | I13: HARGA ROLL | J13: HARGA / PCS
A14: 1 | B14: Benang Jahit | C14: Hitam | D14: =4/100 -> 0.04 | E14: Lusin | F14: 1 lusin jadi 100pc | G14: Toko 1001 | H14: 25000 | J14: =D14*H14 -> 1000
A15: 2 | B15: Benang Obras | C15: Hitam | D15: 0 | E15: Cones | F15: 4 cones jadi 120pc | G15: Toko 1001 | H15: 13000 | J15: =D15*H15 -> 0
A16: 3 | B16: Label Size Bordir | C16: Hitam | D16: =1/100 -> 0.01 | E16: Golong | F16: 1 Golong Jadi 100 pc | G16: Toko 1001 | H16: 10000 | J16: =D16*H16 -> 100
A17: 4 | B17: Plastik Opp 30 Micron | C17: Bening | D17: 1 | E17: Pcs | F17: 1 Plastik 1 Pcs | G17: Mapan Plastik | H17: 370 | J17: =D17*H17 -> 370
A18: 5 | B18: Plastik Pp 50x60cm | C18: Bening | D18: =1/10 -> 0.1 | E18: Pcs | F18: 1 Plastik 10 Pcs | G18: Istana Plastik | H18: 587 | J18: =D18*H18 -> 58.7
A19: 6 | B19: Karung | C19: Putih | D19: =1/100 -> 0.01 | E19: Pcs | F19: 1 karung 100 pcs | G19: Cibadak | H19: 5000 | J19: =D19*H19 -> 50
A20: 7 | B20: DTF | C20: Mix Warna | D20: 1 | E20: Pcs | F20: - | G20: Max Print | H20: 3750 | J20: =D20*H20 -> 3750
A21: Manufaktur
A22: NO | B22: WORK | D22: PEMAKAIAN | E22: UNIT | F22: KET. PEMAKAIAN | G22: VENDOR | H22: ESTIMASI MIN | J22: HARGA / PCS
A23: 1 | B23: Cutting T-Shirt | D23: 1 | E23: Pcs | G23: VML | H23: 750 | J23: =D23*H23 -> 750
A24: 2 | B24: Sablon T-Shirt | D24: 1 | E24: Pcs | G24: VML | H24: 2000 | J24: =D24*H24 -> 2000
A25: 3 | B25: Jahit T-Shirt | D25: 1 | E25: Pcs | G25: VML | H25: 2500 | J25: =D25*H25 -> 2500
A26: 4 | B26: QC T-Shirt | D26: 1 | E26: Pcs | G26: VML | H26: 2000 | J26: =D26*H26 -> 2000

Sheet 17. T-Shirt LS Combed Premium -
B2: T-Shirt L/S Combed Premium - Sablon | C2: Total Harga/Pcs
B3: Bahan | C3: =SUM(J10:J11) -> 39951.429
B4: Aksesoris | C4: =SUM(J14:J20) -> 4328.7
B5: Pekerja | C5: =SUM(J23:J26) -> 7250
B6: Total Biaya Per Pcs | C6: =SUM(C3:D5) -> 51530.129
A8: BAHAN UTAMA
A9: NO | B9: BAHAN | C9: WARNA | D9: PEMAKAIAN | E9: UNIT | F9: KETERANGAN Pemakaian | G9: VENDOR | H9: HARGA ECER | I9: HARGA ROLL | J9: HARGA / PCS
A10: 1 | B10: Cotton Combed Premium | C10: Hitam | D10: =1/3.5 -> 0.28571429 | E10: Kg | F10: 1 kg untuk 3,8 Pcs | G10: CV. Terang Mulia Bandung | H10: 135000 | J10: =D10*H10 -> 38571.429
A11: 2 | B11: Rib Cotton Combed Premium | C11: Hitam | D11: =1/100 -> 0.01 | E11: Kg | F11: 1 Kg untuk 100 Pcs | G11: CV. Terang Mulia Bandung | H11: 138000 | J11: =D11*H11 -> 1380
A12: AKSESORIS
A13: NO | B13: BAHAN | C13: WARNA | D13: PEMAKAIAN | E13: UNIT | F13: KET. PEMAKAIAN | G13: VENDOR | H13: HARGA ECER | I13: HARGA ROLL | J13: HARGA / PCS
A14: 1 | B14: Benang Jahit | C14: Hitam | D14: =5/100 -> 0.05 | E14: Lusin | F14: 1 lusin jadi 100pc | G14: Toko 1001 | H14: 25000 | J14: =D14*H14 -> 1250
A15: 2 | B15: Benang Obras | C15: Hitam | D15: 0 | E15: Cones | F15: 4 cones jadi 120pc | G15: Toko 1001 | H15: 13000 | J15: =D15*H15 -> 0
A16: 3 | B16: Label Size Bordir | C16: Hitam | D16: =1/100 -> 0.01 | E16: Golong | F16: 1 Golong Jadi 100 pc | G16: Toko 1001 | H16: 10000 | J16: =D16*H16 -> 100
A17: 4 | B17: Plastik Opp 30 Micron | C17: Bening | D17: 1 | E17: Pcs | F17: 1 Plastik 1 Pcs | G17: Mapan Plastik | H17: 370 | J17: =D17*H17 -> 370
A18: 5 | B18: Plastik Pp 50x60cm | C18: Bening | D18: =1/10 -> 0.1 | E18: Pcs | F18: 1 Plastik 10 Pcs | G18: Istana Plastik | H18: 587 | J18: =D18*H18 -> 58.7
A19: 6 | B19: Karung | C19: Putih | D19: =1/100 -> 0.01 | E19: Pcs | F19: 1 karung 100 pcs | G19: Cibadak | H19: 5000 | J19: =D19*H19 -> 50
A20: 7 | B20: Cat Sablon Plastisol | C20: Mix Warna | D20: 1 | E20: Pcs | F20: - | G20: Metro SPS | H20: 2500 | J20: =D20*H20 -> 2500
A21: Manufaktur
A22: NO | B22: WORK | D22: PEMAKAIAN | E22: UNIT | F22: KET. PEMAKAIAN | G22: VENDOR | H22: ESTIMASI MIN | J22: HARGA / PCS
A23: 1 | B23: Cutting T-Shirt | D23: 1 | E23: Pcs | G23: VML | H23: 750 | J23: =D23*H23 -> 750
A24: 2 | B24: Sablon T-Shirt | D24: 1 | E24: Pcs | G24: VML | H24: 2000 | J24: =D24*H24 -> 2000
A25: 3 | B25: Jahit T-Shirt | D25: 1 | E25: Pcs | G25: VML | H25: 2500 | J25: =D25*H25 -> 2500
A26: 4 | B26: QC T-Shirt | D26: 1 | E26: Pcs | G26: VML | H26: 2000 | J26: =D26*H26 -> 2000

Sheet 18. T-Shirt LS Combed Reguler -
B2: T-Shirt L/S Combed Reguler - Sablon | C2: Total Harga/Pcs
B3: Bahan | C3: =SUM(J10:J11) -> 34402.857
B4: Aksesoris | C4: =SUM(J14:J20) -> 4328.7
B5: Pekerja | C5: =SUM(J23:J26) -> 7250
B6: Total Biaya Per Pcs | C6: =SUM(C3:D5) -> 45981.557
A8: BAHAN UTAMA
A9: NO | B9: BAHAN | C9: WARNA | D9: PEMAKAIAN | E9: UNIT | F9: KETERANGAN Pemakaian | G9: VENDOR | H9: HARGA ECER | I9: HARGA ROLL | J9: HARGA / PCS
A10: 1 | B10: Cotton Combed Premium | C10: Hitam | D10: =1/3.5 -> 0.28571429 | E10: Kg | F10: 1 kg untuk 3,8 Pcs | G10: Fokus | H10: 116000 | J10: =D10*H10 -> 33142.857
A11: 2 | B11: Rib Cotton Combed Premium | C11: Hitam | D11: =1/100 -> 0.01 | E11: Kg | F11: 1 Kg untuk 100 Pcs | G11: Fokus | H11: 126000 | J11: =D11*H11 -> 1260
A12: AKSESORIS
A13: NO | B13: BAHAN | C13: WARNA | D13: PEMAKAIAN | E13: UNIT | F13: KET. PEMAKAIAN | G13: VENDOR | H13: HARGA ECER | I13: HARGA ROLL | J13: HARGA / PCS
A14: 1 | B14: Benang Jahit | C14: Hitam | D14: =5/100 -> 0.05 | E14: Lusin | F14: 1 lusin jadi 100pc | G14: Toko 1001 | H14: 25000 | J14: =D14*H14 -> 1250
A15: 2 | B15: Benang Obras | C15: Hitam | D15: 0 | E15: Cones | F15: 4 cones jadi 120pc | G15: Toko 1001 | H15: 13000 | J15: =D15*H15 -> 0
A16: 3 | B16: Label Size Bordir | C16: Hitam | D16: =1/100 -> 0.01 | E16: Golong | F16: 1 Golong Jadi 100 pc | G16: Toko 1001 | H16: 10000 | J16: =D16*H16 -> 100
A17: 4 | B17: Plastik Opp 30 Micron | C17: Bening | D17: 1 | E17: Pcs | F17: 1 Plastik 1 Pcs | G17: Mapan Plastik | H17: 370 | J17: =D17*H17 -> 370
A18: 5 | B18: Plastik Pp 50x60cm | C18: Bening | D18: =1/10 -> 0.1 | E18: Pcs | F18: 1 Plastik 10 Pcs | G18: Istana Plastik | H18: 587 | J18: =D18*H18 -> 58.7
A19: 6 | B19: Karung | C19: Putih | D19: =1/100 -> 0.01 | E19: Pcs | F19: 1 karung 100 pcs | G19: Cibadak | H19: 5000 | J19: =D19*H19 -> 50
A20: 7 | B20: Cat Sablon Plastisol | C20: Mix Warna | D20: 1 | E20: Pcs | F20: - | G20: Metro SPS | H20: 2500 | J20: =D20*H20 -> 2500
A21: Manufaktur
A22: NO | B22: WORK | D22: PEMAKAIAN | E22: UNIT | F22: KET. PEMAKAIAN | G22: VENDOR | H22: ESTIMASI MIN | J22: HARGA / PCS
A23: 1 | B23: Cutting T-Shirt | D23: 1 | E23: Pcs | G23: VML | H23: 750 | J23: =D23*H23 -> 750
A24: 2 | B24: Sablon T-Shirt | D24: 1 | E24: Pcs | G24: VML | H24: 2000 | J24: =D24*H24 -> 2000
A25: 3 | B25: Jahit T-Shirt | D25: 1 | E25: Pcs | G25: VML | H25: 2500 | J25: =D25*H25 -> 2500
A26: 4 | B26: QC T-Shirt | D26: 1 | E26: Pcs | G26: VML | H26: 2000 | J26: =D26*H26 -> 2000

Sheet 19. T-Shirt LS Combed Premium -
B2: T-Shirt L/S Combed Premium - DTF | C2: Total Harga/Pcs
B3: Bahan | C3: =SUM(J10:J11) -> 39951.429
B4: Aksesoris | C4: =SUM(J14:J20) -> 5578.7
B5: Pekerja | C5: =SUM(J23:J26) -> 7250
B6: Total Biaya Per Pcs | C6: =SUM(C3:D5) -> 52780.129
A8: BAHAN UTAMA
A9: NO | B9: BAHAN | C9: WARNA | D9: PEMAKAIAN | E9: UNIT | F9: KETERANGAN Pemakaian | G9: VENDOR | H9: HARGA ECER | I9: HARGA ROLL | J9: HARGA / PCS
A10: 1 | B10: Cotton Combed Premium 30s | C10: Hitam | D10: =1/3.5 -> 0.28571429 | E10: Kg | F10: 1 kg untuk 3,8 Pcs | G10: CV. Terang Mulia Bandung | H10: 135000 | J10: =D10*H10 -> 38571.429
A11: 2 | B11: Rib Cotton Combed Premium 30s | C11: Hitam | D11: =1/100 -> 0.01 | E11: Kg | F11: 1 Kg untuk 100 Pcs | G11: CV. Terang Mulia Bandung | H11: 138000 | J11: =D11*H11 -> 1380
A12: AKSESORIS
A13: NO | B13: BAHAN | C13: WARNA | D13: PEMAKAIAN | E13: UNIT | F13: KET. PEMAKAIAN | G13: VENDOR | H13: HARGA ECER | I13: HARGA ROLL | J13: HARGA / PCS
A14: 1 | B14: Benang Jahit | C14: Hitam | D14: =5/100 -> 0.05 | E14: Lusin | F14: 1 lusin jadi 100pc | G14: Toko 1001 | H14: 25000 | J14: =D14*H14 -> 1250
A15: 2 | B15: Benang Obras | C15: Hitam | D15: 0 | E15: Cones | F15: 4 cones jadi 120pc | G15: Toko 1001 | H15: 13000 | J15: =D15*H15 -> 0
A16: 3 | B16: Label Size Bordir | C16: Hitam | D16: =1/100 -> 0.01 | E16: Golong | F16: 1 Golong Jadi 100 pc | G16: Toko 1001 | H16: 10000 | J16: =D16*H16 -> 100
A17: 4 | B17: Plastik Opp 30 Micron | C17: Bening | D17: 1 | E17: Pcs | F17: 1 Plastik 1 Pcs | G17: Mapan Plastik | H17: 370 | J17: =D17*H17 -> 370
A18: 5 | B18: Plastik Pp 50x60cm | C18: Bening | D18: =1/10 -> 0.1 | E18: Pcs | F18: 1 Plastik 10 Pcs | G18: Istana Plastik | H18: 587 | J18: =D18*H18 -> 58.7
A19: 6 | B19: Karung | C19: Putih | D19: =1/100 -> 0.01 | E19: Pcs | F19: 1 karung 100 pcs | G19: Cibadak | H19: 5000 | J19: =D19*H19 -> 50
A20: 7 | B20: DTF | C20: Mix Warna | D20: 1 | E20: Pcs | F20: - | G20: Max Print | H20: 3750 | J20: =D20*H20 -> 3750
A21: Manufaktur
A22: NO | B22: WORK | D22: PEMAKAIAN | E22: UNIT | F22: KET. PEMAKAIAN | G22: VENDOR | H22: ESTIMASI MIN | J22: HARGA / PCS
A23: 1 | B23: Cutting T-Shirt | D23: 1 | E23: Pcs | G23: VML | H23: 750 | J23: =D23*H23 -> 750
A24: 2 | B24: Sablon T-Shirt | D24: 1 | E24: Pcs | G24: VML | H24: 2000 | J24: =D24*H24 -> 2000
A25: 3 | B25: Jahit T-Shirt | D25: 1 | E25: Pcs | G25: VML | H25: 2500 | J25: =D25*H25 -> 2500
A26: 4 | B26: QC T-Shirt | D26: 1 | E26: Pcs | G26: VML | H26: 2000 | J26: =D26*H26 -> 2000

Sheet 20. T-Shirt LS Combed Reguler -
B2: T-Shirt L/S Combed Reguler - DTF | C2: Total Harga/Pcs
B3: Bahan | C3: =SUM(J10:J11) -> 34402.857
B4: Aksesoris | C4: =SUM(J14:J20) -> 5578.7
B5: Pekerja | C5: =SUM(J23:J26) -> 7250
B6: Total Biaya Per Pcs | C6: =SUM(C3:D5) -> 47231.557
A8: BAHAN UTAMA
A9: NO | B9: BAHAN | C9: WARNA | D9: PEMAKAIAN | E9: UNIT | F9: KETERANGAN Pemakaian | G9: VENDOR | H9: HARGA ECER | I9: HARGA ROLL | J9: HARGA / PCS
A10: 1 | B10: Cotton Combed Premium | C10: Hitam | D10: =1/3.5 -> 0.28571429 | E10: Kg | F10: 1 kg untuk 3,8 Pcs | G10: Fokus | H10: 116000 | J10: =D10*H10 -> 33142.857
A11: 2 | B11: Rib Cotton Combed Premium | C11: Hitam | D11: =1/100 -> 0.01 | E11: Kg | F11: 1 Kg untuk 100 Pcs | G11: Fokus | H11: 126000 | J11: =D11*H11 -> 1260
A12: AKSESORIS
A13: NO | B13: BAHAN | C13: WARNA | D13: PEMAKAIAN | E13: UNIT | F13: KET. PEMAKAIAN | G13: VENDOR | H13: HARGA ECER | I13: HARGA ROLL | J13: HARGA / PCS
A14: 1 | B14: Benang Jahit | C14: Hitam | D14: =5/100 -> 0.05 | E14: Lusin | F14: 1 lusin jadi 100pc | G14: Toko 1001 | H14: 25000 | J14: =D14*H14 -> 1250
A15: 2 | B15: Benang Obras | C15: Hitam | D15: 0 | E15: Cones | F15: 4 cones jadi 120pc | G15: Toko 1001 | H15: 13000 | J15: =D15*H15 -> 0
A16: 3 | B16: Label Size Bordir | C16: Hitam | D16: =1/100 -> 0.01 | E16: Golong | F16: 1 Golong Jadi 100 pc | G16: Toko 1001 | H16: 10000 | J16: =D16*H16 -> 100
A17: 4 | B17: Plastik Opp 30 Micron | C17: Bening | D17: 1 | E17: Pcs | F17: 1 Plastik 1 Pcs | G17: Mapan Plastik | H17: 370 | J17: =D17*H17 -> 370
A18: 5 | B18: Plastik Pp 50x60cm | C18: Bening | D18: =1/10 -> 0.1 | E18: Pcs | F18: 1 Plastik 10 Pcs | G18: Istana Plastik | H18: 587 | J18: =D18*H18 -> 58.7
A19: 6 | B19: Karung | C19: Putih | D19: =1/100 -> 0.01 | E19: Pcs | F19: 1 karung 100 pcs | G19: Cibadak | H19: 5000 | J19: =D19*H19 -> 50
A20: 7 | B20: DTF | C20: Mix Warna | D20: 1 | E20: Pcs | F20: - | G20: Max Print | H20: 3750 | J20: =D20*H20 -> 3750
A21: Manufaktur
A22: NO | B22: WORK | D22: PEMAKAIAN | E22: UNIT | F22: KET. PEMAKAIAN | G22: VENDOR | H22: ESTIMASI MIN | J22: HARGA / PCS
A23: 1 | B23: Cutting T-Shirt | D23: 1 | E23: Pcs | G23: VML | H23: 750 | J23: =D23*H23 -> 750
A24: 2 | B24: Sablon T-Shirt | D24: 1 | E24: Pcs | G24: VML | H24: 2000 | J24: =D24*H24 -> 2000
A25: 3 | B25: Jahit T-Shirt | D25: 1 | E25: Pcs | G25: VML | H25: 2500 | J25: =D25*H25 -> 2500
A26: 4 | B26: QC T-Shirt | D26: 1 | E26: Pcs | G26: VML | H26: 2000 | J26: =D26*H26 -> 2000

Sheet 21. T-Shirt Raglan SS Combed Pr
B2: T-Shirt Raglan S/S Combed Premium (3/4)- Sablon | C2: Total Harga/Pcs
B3: Bahan | C3: =SUM(J10:J12) -> 35130
B4: Aksesoris | C4: =SUM(J15:J21) -> 4078.7
B5: Pekerja | C5: =SUM(J24:J27) -> 7550
B6: Total Biaya Per Pcs | C6: =SUM(C3:D5) -> 46758.7
A8: BAHAN UTAMA
A9: NO | B9: BAHAN | C9: WARNA | D9: PEMAKAIAN | E9: UNIT | F9: KETERANGAN Pemakaian | G9: VENDOR | H9: HARGA ECER | I9: HARGA ROLL | J9: HARGA / PCS
A10: 1 | B10: Cotton Combed Premium Badan | C10: Hitam | D10: =1/6 -> 0.16666667 | E10: Kg | F10: 1 kg 6 Pc badan | G10: CV. Terang Mulia Bandung | H10: 135000 | J10: =D10*H10 -> 22500
A11: 2 | B11: Rib Cotton Combed Premium | C11: Hitam | D11: =1/100 -> 0.01 | E11: Kg | F11: 1 kg untuk 100 Pc | G11: CV. Terang Mulia Bandung | H11: 138000 | J11: =D11*H11 -> 1380
A12: 3 | B12: Cotton Combed Premium Badan | C12: Hitam | D12: =1/12 -> 0.083333333 | E12: kg | F12: 1 kg untuk 12 Pc (3/4) | G12: CV. Terang Mulia Bandung | H12: 135000 | J12: =D12*H12 -> 11250
A13: AKSESORIS
A14: NO | B14: BAHAN | C14: WARNA | D14: PEMAKAIAN | E14: UNIT | F14: KET. PEMAKAIAN | G14: VENDOR | H14: HARGA ECER | I14: HARGA ROLL | J14: HARGA / PCS
A15: 1 | B15: Benang Jahit | C15: Hitam | D15: =4/100 -> 0.04 | E15: Lusin | F15: 1 lusin jadi 100pc | G15: Toko 1001 | H15: 25000 | J15: =D15*H15 -> 1000
A16: 2 | B16: Benang Obras | C16: Hitam | D16: 0 | E16: Cones | F16: 4 cones jadi 120pc | G16: Toko 1001 | H16: 13000 | J16: =D16*H16 -> 0
A17: 3 | B17: Label Size Bordir | C17: Hitam | D17: =1/100 -> 0.01 | E17: Golong | F17: 1 Golong Jadi 100 pc | G17: Toko 1001 | H17: 10000 | J17: =D17*H17 -> 100
A18: 4 | B18: Plastik Opp 30 Micron | C18: Bening | D18: 1 | E18: Pcs | F18: 1 Plastik 1 Pcs | G18: Mapan Plastik | H18: 370 | J18: =D18*H18 -> 370
A19: 5 | B19: Plastik Pp 50x60cm | C19: Bening | D19: =1/10 -> 0.1 | E19: Pcs | F19: 1 Plastik 10 Pcs | G19: Istana Plastik | H19: 587 | J19: =D19*H19 -> 58.7
A20: 6 | B20: Karung | C20: Putih | D20: =1/100 -> 0.01 | E20: Pcs | F20: 1 karung 100 pcs | G20: Cibadak | H20: 5000 | J20: =D20*H20 -> 50
A21: 7 | B21: Cat Sablon Plastisol | C21: Mix Warna | D21: 1 | E21: Pcs | F21: - | G21: Metro SPS | H21: 2500 | J21: =D21*H21 -> 2500
A22: Manufaktur
A23: NO | B23: WORK | D23: PEMAKAIAN | E23: UNIT | F23: KET. PEMAKAIAN | G23: VENDOR | H23: ESTIMASI MIN | J23: HARGA / PCS
A24: 1 | B24: Cutting T-Shirt | D24: 1 | E24: Pcs | G24: VML | H24: 750 | J24: =D24*H24 -> 750
A25: 2 | B25: Sablon T-Shirt | D25: 1 | E25: Pcs | G25: VML | H25: 2000 | J25: =D25*H25 -> 2000
A26: 3 | B26: Jahit T-Shirt | D26: 1 | E26: Pcs | G26: VML | H26: 2800 | J26: =D26*H26 -> 2800
A27: 4 | B27: QC T-Shirt | D27: 1 | E27: Pcs | G27: VML | H27: 2000 | J27: =D27*H27 -> 2000

Sheet 22. T-Shirt Raglan SS Combed Re
B2: T-Shirt Raglan S/S Combed Premium (3/4)- Sablon | C2: Total Harga/Pcs
B3: Bahan | C3: =SUM(J10:J12) -> 30780
B4: Aksesoris | C4: =SUM(J15:J21) -> 4078.7
B5: Pekerja | C5: =SUM(J24:J27) -> 7250
B6: Total Biaya Per Pcs | C6: =SUM(C3:D5) -> 42108.7
A8: BAHAN UTAMA
A9: NO | B9: BAHAN | C9: WARNA | D9: PEMAKAIAN | E9: UNIT | F9: KETERANGAN Pemakaian | G9: VENDOR | H9: HARGA ECER | I9: HARGA ROLL | J9: HARGA / PCS
A10: 1 | B10: Cotton Combed Premium Badan | C10: Hitam | D10: =1/6 -> 0.16666667 | E10: Kg | F10: 1 kg 6 Pc badan | G10: Fokus | H10: 118000 | J10: =D10*H10 -> 19666.667
A11: 2 | B11: Rib Cotton Combed Premium | C11: Hitam | D11: =1/100 -> 0.01 | E11: Kg | F11: 1 kg untuk 100 Pc | G11: Fokus | H11: 128000 | J11: =D11*H11 -> 1280
A12: 3 | B12: Cotton Combed Premium Badan | C12: Hitam | D12: =1/12 -> 0.083333333 | E12: kg | F12: 1 kg untuk 12 Pc (3/4) | G12: Fokus | H12: 118000 | J12: =D12*H12 -> 9833.3333
A13: AKSESORIS
A14: NO | B14: BAHAN | C14: WARNA | D14: PEMAKAIAN | E14: UNIT | F14: KET. PEMAKAIAN | G14: VENDOR | H14: HARGA ECER | I14: HARGA ROLL | J14: HARGA / PCS
A15: 1 | B15: Benang Jahit | C15: Hitam | D15: =4/100 -> 0.04 | E15: Lusin | F15: 1 lusin jadi 100pc | G15: Toko 1001 | H15: 25000 | J15: =D15*H15 -> 1000
A16: 2 | B16: Benang Obras | C16: Hitam | D16: 0 | E16: Cones | F16: 4 cones jadi 120pc | G16: Toko 1001 | H16: 13000 | J16: =D16*H16 -> 0
A17: 3 | B17: Label Size Bordir | C17: Hitam | D17: =1/100 -> 0.01 | E17: Golong | F17: 1 Golong Jadi 100 pc | G17: Toko 1001 | H17: 10000 | J17: =D17*H17 -> 100
A18: 4 | B18: Plastik Opp 30 Micron | C18: Bening | D18: 1 | E18: Pcs | F18: 1 Plastik 1 Pcs | G18: Mapan Plastik | H18: 370 | J18: =D18*H18 -> 370
A19: 5 | B19: Plastik Pp 50x60cm | C19: Bening | D19: =1/10 -> 0.1 | E19: Pcs | F19: 1 Plastik 10 Pcs | G19: Istana Plastik | H19: 587 | J19: =D19*H19 -> 58.7
A20: 6 | B20: Karung | C20: Putih | D20: =1/100 -> 0.01 | E20: Pcs | F20: 1 karung 100 pcs | G20: Cibadak | H20: 5000 | J20: =D20*H20 -> 50
A21: 7 | B21: Cat Sablon Plastisol | C21: Mix Warna | D21: 1 | E21: Pcs | F21: - | G21: Metro SPS | H21: 2500 | J21: =D21*H21 -> 2500
A22: Manufaktur
A23: NO | B23: WORK | D23: PEMAKAIAN | E23: UNIT | F23: KET. PEMAKAIAN | G23: VENDOR | H23: ESTIMASI MIN | J23: HARGA / PCS
A24: 1 | B24: Cutting T-Shirt | D24: 1 | E24: Pcs | G24: VML | H24: 750 | J24: =D24*H24 -> 750
A25: 2 | B25: Sablon T-Shirt | D25: 1 | E25: Pcs | G25: VML | H25: 2000 | J25: =D25*H25 -> 2000
A26: 3 | B26: Jahit T-Shirt | D26: 1 | E26: Pcs | G26: VML | H26: 2500 | J26: =D26*H26 -> 2500
A27: 4 | B27: QC T-Shirt | D27: 1 | E27: Pcs | G27: VML | H27: 2000 | J27: =D27*H27 -> 2000

Sheet 23. T-Shirt Raglan SS Combed Pr
B2: T-Shirt Raglan S/S Combed Premium (3/4)- DTF | C2: Total Harga/Pcs
B3: Bahan | C3: =SUM(J10:J12) -> 35130
B4: Aksesoris | C4: =SUM(J15:J21) -> 5328.7
B5: Pekerja | C5: =SUM(J24:J27) -> 7250
B6: Total Biaya Per Pcs | C6: =SUM(C3:D5) -> 47708.7
A8: BAHAN UTAMA
A9: NO | B9: BAHAN | C9: WARNA | D9: PEMAKAIAN | E9: UNIT | F9: KETERANGAN Pemakaian | G9: VENDOR | H9: HARGA ECER | I9: HARGA ROLL | J9: HARGA / PCS
A10: 1 | B10: Cotton Combed Premium Badan | C10: Hitam | D10: =1/6 -> 0.16666667 | E10: Kg | F10: 1 kg 6 Pc badan | G10: CV. Terang Mulia Bandung | H10: 135000 | J10: =D10*H10 -> 22500
A11: 2 | B11: Rib Cotton Combed Premium | C11: Hitam | D11: =1/100 -> 0.01 | E11: Kg | F11: 1 kg untuk 100 Pc | G11: CV. Terang Mulia Bandung | H11: 138000 | J11: =D11*H11 -> 1380
A12: 3 | B12: Cotton Combed Premium Badan | C12: Hitam | D12: =1/12 -> 0.083333333 | E12: kg | F12: 1 kg untuk 12 Pc (3/4) | G12: CV. Terang Mulia Bandung | H12: 135000 | J12: =D12*H12 -> 11250
A13: AKSESORIS
A14: NO | B14: BAHAN | C14: WARNA | D14: PEMAKAIAN | E14: UNIT | F14: KET. PEMAKAIAN | G14: VENDOR | H14: HARGA ECER | I14: HARGA ROLL | J14: HARGA / PCS
A15: 1 | B15: Benang Jahit | C15: Hitam | D15: =4/100 -> 0.04 | E15: Lusin | F15: 1 lusin jadi 100pc | G15: Toko 1001 | H15: 25000 | J15: =D15*H15 -> 1000
A16: 2 | B16: Benang Obras | C16: Hitam | D16: 0 | E16: Cones | F16: 4 cones jadi 120pc | G16: Toko 1001 | H16: 13000 | J16: =D16*H16 -> 0
A17: 3 | B17: Label Size Bordir | C17: Hitam | D17: =1/100 -> 0.01 | E17: Golong | F17: 1 Golong Jadi 100 pc | G17: Toko 1001 | H17: 10000 | J17: =D17*H17 -> 100
A18: 4 | B18: Plastik Opp 30 Micron | C18: Bening | D18: 1 | E18: Pcs | F18: 1 Plastik 1 Pcs | G18: Mapan Plastik | H18: 370 | J18: =D18*H18 -> 370
A19: 5 | B19: Plastik Pp 50x60cm | C19: Bening | D19: =1/10 -> 0.1 | E19: Pcs | F19: 1 Plastik 10 Pcs | G19: Istana Plastik | H19: 587 | J19: =D19*H19 -> 58.7
A20: 6 | B20: Karung | C20: Putih | D20: =1/100 -> 0.01 | E20: Pcs | F20: 1 karung 100 pcs | G20: Cibadak | H20: 5000 | J20: =D20*H20 -> 50
A21: 7 | B21: DTF | C21: Mix Warna | D21: 1 | E21: Pcs | F21: - | G21: Max Print | H21: 3750 | J21: =D21*H21 -> 3750
A22: Manufaktur
A23: NO | B23: WORK | D23: PEMAKAIAN | E23: UNIT | F23: KET. PEMAKAIAN | G23: VENDOR | H23: ESTIMASI MIN | J23: HARGA / PCS
A24: 1 | B24: Cutting T-Shirt | D24: 1 | E24: Pcs | G24: VML | H24: 750 | J24: =D24*H24 -> 750
A25: 2 | B25: Sablon T-Shirt | D25: 1 | E25: Pcs | G25: VML | H25: 2000 | J25: =D25*H25 -> 2000
A26: 3 | B26: Jahit T-Shirt | D26: 1 | E26: Pcs | G26: VML | H26: 2500 | J26: =D26*H26 -> 2500
A27: 4 | B27: QC T-Shirt | D27: 1 | E27: Pcs | G27: VML | H27: 2000 | J27: =D27*H27 -> 2000

Sheet 24. T-Shirt Raglan SS Combed Re
B2: T-Shirt Raglan S/S Combed reguler (3/4)- Sablon | C2: Total Harga/Pcs
B3: Bahan | C3: =SUM(J10:J12) -> 30780
B4: Aksesoris | C4: =SUM(J15:J21) -> 5328.7
B5: Pekerja | C5: =SUM(J24:J27) -> 7250
B6: Total Biaya Per Pcs | C6: =SUM(C3:D5) -> 43358.7
A8: BAHAN UTAMA
A9: NO | B9: BAHAN | C9: WARNA | D9: PEMAKAIAN | E9: UNIT | F9: KETERANGAN Pemakaian | G9: VENDOR | H9: HARGA ECER | I9: HARGA ROLL | J9: HARGA / PCS
A10: 1 | B10: Cotton Combed Premium Badan | C10: Hitam | D10: =1/6 -> 0.16666667 | E10: Kg | F10: 1 kg 6 Pc badan | G10: Fokus | H10: 118000 | J10: =D10*H10 -> 19666.667
A11: 2 | B11: Rib Cotton Combed Premium | C11: Hitam | D11: =1/100 -> 0.01 | E11: Kg | F11: 1 kg untuk 100 Pc | G11: Fokus | H11: 128000 | J11: =D11*H11 -> 1280
A12: 3 | B12: Cotton Combed Premium Badan | C12: Hitam | D12: =1/12 -> 0.083333333 | E12: kg | F12: 1 kg untuk 12 Pc (3/4) | G12: Fokus | H12: 118000 | J12: =D12*H12 -> 9833.3333
A13: AKSESORIS
A14: NO | B14: BAHAN | C14: WARNA | D14: PEMAKAIAN | E14: UNIT | F14: KET. PEMAKAIAN | G14: VENDOR | H14: HARGA ECER | I14: HARGA ROLL | J14: HARGA / PCS
A15: 1 | B15: Benang Jahit | C15: Hitam | D15: =4/100 -> 0.04 | E15: Lusin | F15: 1 lusin jadi 100pc | G15: Toko 1001 | H15: 25000 | J15: =D15*H15 -> 1000
A16: 2 | B16: Benang Obras | C16: Hitam | D16: 0 | E16: Cones | F16: 4 cones jadi 120pc | G16: Toko 1001 | H16: 13000 | J16: =D16*H16 -> 0
A17: 3 | B17: Label Size Bordir | C17: Hitam | D17: =1/100 -> 0.01 | E17: Golong | F17: 1 Golong Jadi 100 pc | G17: Toko 1001 | H17: 10000 | J17: =D17*H17 -> 100
A18: 4 | B18: Plastik Opp 30 Micron | C18: Bening | D18: 1 | E18: Pcs | F18: 1 Plastik 1 Pcs | G18: Mapan Plastik | H18: 370 | J18: =D18*H18 -> 370
A19: 5 | B19: Plastik Pp 50x60cm | C19: Bening | D19: =1/10 -> 0.1 | E19: Pcs | F19: 1 Plastik 10 Pcs | G19: Istana Plastik | H19: 587 | J19: =D19*H19 -> 58.7
A20: 6 | B20: Karung | C20: Putih | D20: =1/100 -> 0.01 | E20: Pcs | F20: 1 karung 100 pcs | G20: Cibadak | H20: 5000 | J20: =D20*H20 -> 50
A21: 7 | B21: DTF | C21: Mix Warna | D21: 1 | E21: Pcs | F21: - | G21: Max Print | H21: 3750 | J21: =D21*H21 -> 3750
A22: Manufaktur
A23: NO | B23: WORK | D23: PEMAKAIAN | E23: UNIT | F23: KET. PEMAKAIAN | G23: VENDOR | H23: ESTIMASI MIN | J23: HARGA / PCS
A24: 1 | B24: Cutting T-Shirt | D24: 1 | E24: Pcs | G24: VML | H24: 750 | J24: =D24*H24 -> 750
A25: 2 | B25: Sablon T-Shirt | D25: 1 | E25: Pcs | G25: VML | H25: 2000 | J25: =D25*H25 -> 2000
A26: 3 | B26: Jahit T-Shirt | D26: 1 | E26: Pcs | G26: VML | H26: 2500 | J26: =D26*H26 -> 2500
A27: 4 | B27: QC T-Shirt | D27: 1 | E27: Pcs | G27: VML | H27: 2000 | J27: =D27*H27 -> 2000

Sheet 25. T-Shirt Raglan LS Combed Pr
B2: T-Shirt Raglan L/S Combed Premium - Sablon | C2: Total Harga/Pcs
B3: Bahan | C3: =SUM(J10:J12) -> 39762.353
B4: Aksesoris | C4: =SUM(J15:J21) -> 4078.7
B5: Pekerja | C5: =SUM(J24:J27) -> 7250
B6: Total Biaya Per Pcs | C6: =SUM(C3:D5) -> 51091.053
A8: BAHAN UTAMA
A9: NO | B9: BAHAN | C9: WARNA | D9: PEMAKAIAN | E9: UNIT | F9: KETERANGAN Pemakaian | G9: VENDOR | H9: HARGA ECER | I9: HARGA ROLL | J9: HARGA / PCS
A10: 1 | B10: Cotton Combed Premium Badan | C10: Hitam | D10: =1/6 -> 0.16666667 | E10: Kg | F10: 1 kg 6 Pc badan | G10: CV. Terang Mulia Bandung | H10: 135000 | J10: =D10*H10 -> 22500
A11: 2 | B11: Rib Cotton Combed Premium | C11: Hitam | D11: =1/100 -> 0.01 | E11: Kg | F11: 1 kg untuk 100 Pc | G11: CV. Terang Mulia Bandung | H11: 138000 | J11: =D11*H11 -> 1380
A12: 3 | B12: Cotton Combed Premium Badan | C12: Hitam | D12: =1/8.5 -> 0.11764706 | E12: kg | F12: 1 kg untuk 8.5 Pc | G12: CV. Terang Mulia Bandung | H12: 135000 | J12: =D12*H12 -> 15882.353
A13: AKSESORIS
